<sdf version='1.6'>
  <world name='default'>
    <light name='sun' type='directional'>
      <cast_shadows>1</cast_shadows>
      <pose frame=''>0 0 10 0 -0 0</pose>
      <diffuse>0.8 0.8 0.8 1</diffuse>
      <specular>0.1 0.1 0.1 1</specular>
      <attenuation>
        <range>1000</range>
        <constant>0.9</constant>
        <linear>0.01</linear>
        <quadratic>0.001</quadratic>
      </attenuation>
      <direction>-0.5 0.5 -1</direction>
    </light>
    <model name='ground_plane'>
      <static>1</static>
      <link name='link'>
        <collision name='collision'>
          <geometry>
            <plane>
              <normal>0 0 1</normal>
              <size>100 100</size>
            </plane>
          </geometry>
          <surface>
            <friction>
              <ode>
                <mu>100</mu>
                <mu2>50</mu2>
              </ode>
              <torsional>
                <ode/>
              </torsional>
            </friction>
            <contact>
              <ode/>
            </contact>
            <bounce/>
          </surface>
          <max_contacts>10</max_contacts>
        </collision>
        <visual name='visual'>
          <cast_shadows>0</cast_shadows>
          <geometry>
            <plane>
              <normal>0 0 1</normal>
              <size>100 100</size>
            </plane>
          </geometry>
          <material>
            <script>
              <uri>file://media/materials/scripts/gazebo.material</uri>
              <name>Gazebo/Grey</name>
            </script>
          </material>
        </visual>
        <self_collide>0</self_collide>
        <kinematic>0</kinematic>
        <gravity>1</gravity>
      </link>
    </model>
    <gravity>0 0 -9.8</gravity>
    <magnetic_field>6e-06 2.3e-05 -4.2e-05</magnetic_field>
    <atmosphere type='adiabatic'/>
    <physics name='default_physics' default='0' type='ode'>
      <max_step_size>0.001</max_step_size>
      <real_time_factor>1</real_time_factor>
      <real_time_update_rate>1000</real_time_update_rate>
    </physics>
    <scene>
      <ambient>0.4 0.4 0.4 1</ambient>
      <background>0.7 0.7 0.7 1</background>
      <shadows>1</shadows>
    </scene>
    <spherical_coordinates>
      <surface_model>EARTH_WGS84</surface_model>
      <latitude_deg>0</latitude_deg>
      <longitude_deg>0</longitude_deg>
      <elevation>0</elevation>
      <heading_deg>0</heading_deg>
    </spherical_coordinates>
    <model name='hku_m100'>
      <link name='base_link'>
        <pose frame=''>0 0 0 0 -0 0</pose>
        <inertial>
          <pose frame=''>0 0 0 0 -0 0</pose>
          <mass>1.477</mass>
          <inertia>
            <ixx>0.01152</ixx>
            <ixy>0</ixy>
            <ixz>0</ixz>
            <iyy>0.01152</iyy>
            <iyz>0</iyz>
            <izz>0.0218</izz>
          </inertia>
        </inertial>
        <collision name='base_link_collision'>
          <pose frame=''>0 0 0 0 -0 0</pose>
          <geometry>
            <mesh>
              <scale>1 1 1</scale>
              <uri>/home/mumu1408/m100_ws/src/hku_m100_description/meshes/hku_m100/hku_m100.stl</uri>
            </mesh>
          </geometry>
          <max_contacts>10</max_contacts>
          <surface>
            <contact>
              <ode/>
            </contact>
            <bounce/>
            <friction>
              <torsional>
                <ode/>
              </torsional>
              <ode/>
            </friction>
          </surface>
        </collision>
        <visual name='base_link_visual'>
          <pose frame=''>0 0 0 0 -0 0</pose>
          <geometry>
            <mesh>
              <scale>1 1 1</scale>
              <uri>/home/mumu1408/m100_ws/src/hku_m100_description/meshes/hku_m100/hku_m100.dae</uri>
            </mesh>
          </geometry>
        </visual>
        <self_collide>0</self_collide>
        <kinematic>0</kinematic>
        <gravity>1</gravity>
      </link>
      <link name='gimbal_link'>
        <pose frame=''>0 0 0 0 -0 0</pose>
        <inertial>
          <pose frame=''>0 0 0 0 -0 0</pose>
          <mass>0.001</mass>
          <inertia>
            <ixx>0.0001</ixx>
            <ixy>0</ixy>
            <ixz>0</ixz>
            <iyy>0.0001</iyy>
            <iyz>0</iyz>
            <izz>0.0001</izz>
          </inertia>
        </inertial>
        <visual name='gimbal_link_visual'>
          <pose frame=''>0.1 0 -0.04 0 -0 0</pose>
          <geometry>
            <box>
              <size>0.001 0.001 0.001</size>
            </box>
          </geometry>
        </visual>
        <self_collide>0</self_collide>
        <kinematic>0</kinematic>
        <gravity>1</gravity>
      </link>
      <joint name='gimbal_joint' type='revolute'>
        <child>gimbal_link</child>
        <parent>base_link</parent>
        <axis>
          <xyz>1 0 0</xyz>
          <limit>
            <lower>0</lower>
            <upper>0</upper>
            <effort>1000</effort>
            <velocity>0.5</velocity>
          </limit>
          <dynamics>
            <spring_reference>0</spring_reference>
            <spring_stiffness>0</spring_stiffness>
          </dynamics>
          <use_parent_model_frame>1</use_parent_model_frame>
        </axis>
      </joint>
      <link name='yaw_link'>
        <pose frame=''>0 0 0 0 -0 0</pose>
        <inertial>
          <pose frame=''>0 0 0 0 -0 0</pose>
          <mass>0.001</mass>
          <inertia>
            <ixx>0.0001</ixx>
            <ixy>0</ixy>
            <ixz>0</ixz>
            <iyy>0.0001</iyy>
            <iyz>0</iyz>
            <izz>0.0001</izz>
          </inertia>
        </inertial>
        <visual name='yaw_link_visual'>
          <pose frame=''>0.1 0 -0.04 0 -0 0</pose>
          <geometry>
            <box>
              <size>0.001 0.001 0.001</size>
            </box>
          </geometry>
        </visual>
        <self_collide>0</self_collide>
        <kinematic>0</kinematic>
        <gravity>1</gravity>
      </link>
      <joint name='base_yaw_joint' type='revolute'>
        <child>yaw_link</child>
        <parent>gimbal_link</parent>
        <axis>
          <xyz>0 0 1</xyz>
          <limit>
            <lower>-1e+16</lower>
            <upper>1e+16</upper>
            <effort>1000</effort>
            <velocity>0.5</velocity>
          </limit>
          <dynamics>
            <spring_reference>0</spring_reference>
            <spring_stiffness>0</spring_stiffness>
          </dynamics>
          <use_parent_model_frame>1</use_parent_model_frame>
        </axis>
      </joint>
      <link name='roll_link'>
        <pose frame=''>0 0 0 0 -0 0</pose>
        <inertial>
          <pose frame=''>0 0 0 0 -0 0</pose>
          <mass>0.001</mass>
          <inertia>
            <ixx>0.0001</ixx>
            <ixy>0</ixy>
            <ixz>0</ixz>
            <iyy>0.0001</iyy>
            <iyz>0</iyz>
            <izz>0.0001</izz>
          </inertia>
        </inertial>
        <visual name='roll_link_visual'>
          <pose frame=''>0.1 0 -0.04 0 -0 0</pose>
          <geometry>
            <box>
              <size>0.001 0.001 0.001</size>
            </box>
          </geometry>
        </visual>
        <self_collide>0</self_collide>
        <kinematic>0</kinematic>
        <gravity>1</gravity>
      </link>
      <joint name='yaw_roll_joint' type='revolute'>
        <child>roll_link</child>
        <parent>yaw_link</parent>
        <axis>
          <xyz>1 0 0</xyz>
          <limit>
            <lower>-1e+16</lower>
            <upper>1e+16</upper>
            <effort>1000</effort>
            <velocity>0.5</velocity>
          </limit>
          <dynamics>
            <spring_reference>0</spring_reference>
            <spring_stiffness>0</spring_stiffness>
          </dynamics>
          <use_parent_model_frame>1</use_parent_model_frame>
        </axis>
      </joint>
      <link name='pitch_link'>
        <pose frame=''>0 0 0 0 -0 0</pose>
        <inertial>
          <pose frame=''>0 0 0 0 -0 0</pose>
          <mass>0.001</mass>
          <inertia>
            <ixx>0.0001</ixx>
            <ixy>0</ixy>
            <ixz>0</ixz>
            <iyy>0.0001</iyy>
            <iyz>0</iyz>
            <izz>0.0001</izz>
          </inertia>
        </inertial>
        <visual name='pitch_link_visual'>
          <pose frame=''>0.1 0 -0.04 0 -0 0</pose>
          <geometry>
            <box>
              <size>0.001 0.001 0.001</size>
            </box>
          </geometry>
        </visual>
        <self_collide>0</self_collide>
        <kinematic>0</kinematic>
        <gravity>1</gravity>
      </link>
      <joint name='roll_pitch_joint' type='revolute'>
        <child>pitch_link</child>
        <parent>roll_link</parent>
        <axis>
          <xyz>0 1 0</xyz>
          <limit>
            <lower>-1e+16</lower>
            <upper>1e+16</upper>
            <effort>1000</effort>
            <velocity>0.5</velocity>
          </limit>
          <dynamics>
            <spring_reference>0</spring_reference>
            <spring_stiffness>0</spring_stiffness>
          </dynamics>
          <use_parent_model_frame>1</use_parent_model_frame>
        </axis>
      </joint>
      <link name='camera_link'>
        <pose frame=''>0 0 0 0 -0 0</pose>
        <inertial>
          <pose frame=''>0 0 0 0 -0 0</pose>
          <mass>0.001</mass>
          <inertia>
            <ixx>0.0001</ixx>
            <ixy>0</ixy>
            <ixz>0</ixz>
            <iyy>0.0001</iyy>
            <iyz>0</iyz>
            <izz>0.0001</izz>
          </inertia>
        </inertial>
        <collision name='camera_link_collision'>
          <pose frame=''>0.1 0 -0.04 0 -0 0</pose>
          <geometry>
            <mesh>
              <scale>1 1 1</scale>
              <uri>/home/mumu1408/m100_ws/src/hku_m100_description/meshes/hku_m100/gimbal.stl</uri>
            </mesh>
          </geometry>
          <surface>
            <contact>
              <ode/>
            </contact>
            <friction>
              <ode/>
              <torsional>
                <ode/>
              </torsional>
            </friction>
            <bounce/>
          </surface>
          <max_contacts>10</max_contacts>
        </collision>
        <visual name='camera_link_visual'>
          <pose frame=''>0.1 0 -0.04 0 -0 0</pose>
          <geometry>
            <mesh>
              <scale>1 1 1</scale>
              <uri>/home/mumu1408/m100_ws/src/hku_m100_description/meshes/hku_m100/gimbal.dae</uri>
            </mesh>
          </geometry>
          <material>
            <script>
              <uri>__default__</uri>
              <name>__default__</name>
            </script>
          </material>
        </visual>
        <gravity>1</gravity>
        <velocity_decay/>
        <self_collide>0</self_collide>
        <sensor name='camera_camera_sensor' type='camera'>
          <update_rate>10</update_rate>
          <camera name='__default__'>
            <pose frame=''>0.027 0 -0.027 0 -0 0</pose>
            <horizontal_fov>1.64061</horizontal_fov>
            <image>
              <format>R8G8B8</format>
              <width>640</width>
              <height>480</height>
            </image>
            <clip>
              <near>0.01</near>
              <far>100</far>
            </clip>
          </camera>
          <plugin name='camera_controller' filename='libgazebo_ros_camera.so'>
            <cameraName>camera</cameraName>
            <alwaysOn>true</alwaysOn>
            <updateRate>10</updateRate>
            <imageTopicName>/dji_sdk/image_raw</imageTopicName>
            <cameraInfoTopicName>/dji_sdk/camera_info</cameraInfoTopicName>
            <frameName>camera_optical_frame</frameName>
            <robotNamespace>/</robotNamespace>
          </plugin>
        </sensor>
        <kinematic>0</kinematic>
      </link>
      <joint name='camera_joint' type='revolute'>
        <child>camera_link</child>
        <parent>pitch_link</parent>
        <axis>
          <xyz>0 1 0</xyz>
          <limit>
            <lower>-0</lower>
            <upper>0</upper>
            <effort>1000</effort>
            <velocity>0.5</velocity>
          </limit>
          <dynamics>
            <spring_reference>0</spring_reference>
            <spring_stiffness>0</spring_stiffness>
          </dynamics>
          <use_parent_model_frame>1</use_parent_model_frame>
        </axis>
      </joint>
      <pose frame=''>3 3 0.3 0 -0 0</pose>
    </model>
    <state world_name='default'>
      <sim_time>27 476000000</sim_time>
      <real_time>44 843422832</real_time>
      <wall_time>1546514856 511336120</wall_time>
      <iterations>27476</iterations>
      <model name='ground_plane'>
        <pose frame=''>0 0 0 0 -0 0</pose>
        <scale>1 1 1</scale>
        <link name='link'>
          <pose frame=''>0 0 0 0 -0 0</pose>
          <velocity>0 0 0 0 -0 0</velocity>
          <acceleration>0 0 0 0 -0 0</acceleration>
          <wrench>0 0 0 0 -0 0</wrench>
        </link>
      </model>
      <model name='hku_m100'>
        <pose frame=''>2.99188 2.9958 0.113352 0.000102 -2.1e-05 0.118075</pose>
        <scale>1 1 1</scale>
        <link name='base_link'>
          <pose frame=''>2.99188 2.9958 0.113352 0.000102 -2.1e-05 0.118075</pose>
          <velocity>0.000433 -0.004916 -0.008321 0.081092 0.009658 -0.003071</velocity>
          <acceleration>4.00341 -12.978 3.17749 1.50152 -0.072184 2.64365</acceleration>
          <wrench>5.91303 -19.1685 4.69315 0 -0 0</wrench>
        </link>
        <link name='camera_link'>
          <pose frame=''>2.99188 2.9958 0.113352 0.020117 0.004695 -0.667095</pose>
          <velocity>0.000384 -0.004892 -0.00831 0.002002 -0.000592 -0.038402</velocity>
          <acceleration>3.88788 -12.7713 3.25159 0.016599 0.019129 -1.25984</acceleration>
          <wrench>0.003888 -0.012771 0.003252 0 -0 0</wrench>
        </link>
        <link name='gimbal_link'>
          <pose frame=''>2.99188 2.9958 0.113352 0.000101 -1.5e-05 0.118078</pose>
          <velocity>0.000441 -0.004919 -0.008323 0.080754 0.009435 -0.003377</velocity>
          <acceleration>4.00978 -12.9474 3.17284 1.43029 -0.077955 2.39551</acceleration>
          <wrench>0.00401 -0.012947 0.003173 0 -0 0</wrench>
        </link>
        <link name='pitch_link'>
          <pose frame=''>2.99188 2.9958 0.113352 0.020117 0.004695 -0.667095</pose>
          <velocity>0.000396 -0.004899 -0.008314 0.002002 -0.000592 -0.038402</velocity>
          <acceleration>3.91559 -12.8068 3.23572 0.016657 0.019202 -1.25982</acceleration>
          <wrench>0.003916 -0.012807 0.003236 0 -0 0</wrench>
        </link>
        <link name='roll_link'>
          <pose frame=''>2.99188 2.9958 0.113352 0.020117 5.8e-05 -0.667188</pose>
          <velocity>0.000408 -0.004906 -0.008317 0.037091 0.043958 -0.037261</velocity>
          <acceleration>3.94753 -12.8496 3.21653 -1.13554 -0.889464 -1.88535</acceleration>
          <wrench>0.003948 -0.01285 0.003217 0 -0 0</wrench>
        </link>
        <link name='yaw_link'>
          <pose frame=''>2.99188 2.9958 0.113352 8.5e-05 5.8e-05 -0.667188</pose>
          <velocity>0.00042 -0.004913 -0.00832 0.080755 0.009564 -0.037263</velocity>
          <acceleration>3.9806 -12.8973 3.19519 1.45181 -0.020366 -1.89066</acceleration>
          <wrench>0.003981 -0.012897 0.003195 0 -0 0</wrench>
        </link>
      </model>
      <light name='sun'>
        <pose frame=''>0 0 10 0 -0 0</pose>
      </light>
    </state>
    <gui fullscreen='0'>
      <camera name='user_camera'>
        <pose frame=''>4.26609 2.25437 0.474025 0 0.275643 2.35619</pose>
        <view_controller>orbit</view_controller>
        <projection_type>perspective</projection_type>
      </camera>
    </gui>
  </world>
</sdf>
